Outputs (Seed=722)/Order Generator Output.txt
D:\Athul\Quant Development\Matching Engine>g++ order_generator.cpp -o client.exe -lws2_32 && client.exe
1. { SELL, 100.750000, 75 }
2. { SELL, 101.750000, 100 }
3. { BUY, 100.750000, 75 }
4. { BUY, 101.000000, 75 }
5. { SELL, 100.500000, 75 }
6. { BUY, 100.750000, 100 }
7. { BUY, 101.250000, 25 }
8. { SELL, 101.250000, 25 }
9. { BUY, 101.000000, 100 }
10. { BUY, 101.500000, 75 }
11. { SELL, 101.000000, 25 }
12. { BUY, 100.750000, 75 }
13. { SELL, 100.750000, 25 }
14. { BUY, 101.500000, 75 }
15. { BUY, 100.500000, 25 }
16. { BUY, 101.000000, 100 }
17. { BUY, 100.500000, 25 }
18. { SELL, 101.500000, 75 }
19. { SELL, 100.750000, 100 }
20. { SELL, 101.250000, 75 }
21. { BUY, 101.750000, 25 }
22. { BUY, 101.000000, 75 }
23. { BUY, 102.000000, 25 }
24. { SELL, 100.000000, 25 }
25. { BUY, 101.000000, 100 }
26. { SELL, 101.250000, 75 }
27. { BUY, 101.750000, 100 }
28. { BUY, 100.000000, 75 }
29. { SELL, 101.500000, 50 }
30. { BUY, 100.250000, 100 }
31. { BUY, 100.000000, 50 }
32. { SELL, 100.250000, 50 }
33. { BUY, 101.000000, 50 }
34. { SELL, 100.750000, 25 }
35. { BUY, 100.000000, 25 }
36. { SELL, 101.250000, 100 }
37. { BUY, 102.000000, 25 }
38. { SELL, 100.750000, 100 }
39. { BUY, 101.500000, 25 }
40. { SELL, 101.500000, 25 }
41. { SELL, 100.750000, 100 }
42. { BUY, 101.000000, 75 }
43. { SELL, 100.000000, 25 }
44. { SELL, 102.000000, 75 }
45. { BUY, 100.000000, 75 }
46. { SELL, 100.750000, 100 }
47. { BUY, 100.750000, 75 }
48. { SELL, 101.500000, 100 }
49. { SELL, 102.000000, 75 }
50. { BUY, 102.000000, 75 }
51. { BUY, 101.250000, 75 }
52. { SELL, 101.000000, 75 }
53. { SELL, 102.000000, 75 }
54. { SELL, 100.500000, 75 }
55. { SELL, 102.000000, 25 }
56. { BUY, 100.000000, 100 }
57. { BUY, 100.000000, 50 }
58. { SELL, 101.750000, 100 }
59. { SELL, 100.750000, 75 }
60. { BUY, 101.500000, 100 }
61. { SELL, 100.000000, 100 }
62. { SELL, 101.500000, 100 }
63. { BUY, 101.000000, 50 }
64. { BUY, 101.000000, 25 }
65. { SELL, 100.500000, 50 }
66. { SELL, 100.250000, 50 }
67. { SELL, 101.250000, 25 }
68. { SELL, 100.750000, 75 }
69. { SELL, 101.250000, 100 }
70. { SELL, 101.000000, 75 }
71. { SELL, 100.000000, 100 }
72. { SELL, 102.000000, 25 }
73. { BUY, 101.500000, 100 }
74. { SELL, 101.500000, 25 }
75. { SELL, 101.500000, 75 }
76. { SELL, 100.750000, 25 }
77. { BUY, 100.750000, 50 }
78. { BUY, 100.500000, 25 }
79. { SELL, 101.250000, 100 }
80. { BUY, 101.500000, 75 }
81. { BUY, 100.750000, 25 }
82. { SELL, 101.750000, 25 }
83. { BUY, 101.250000, 50 }
84. { SELL, 101.250000, 25 }
85. { BUY, 101.500000, 100 }
86. { SELL, 102.000000, 25 }
87. { SELL, 100.250000, 50 }
88. { SELL, 100.250000, 75 }
89. { SELL, 101.750000, 100 }
90. { SELL, 100.750000, 100 }
91. { BUY, 100.500000, 50 }
92. { SELL, 100.000000, 25 }
93. { BUY, 101.000000, 75 }
94. { BUY, 100.000000, 75 }
95. { BUY, 100.750000, 25 }
96. { BUY, 101.500000, 100 }
97. { SELL, 101.250000, 100 }
98. { SELL, 100.750000, 25 }
99. { BUY, 100.750000, 25 }
100. { BUY, 101.000000, 100 }
101. { BUY, 100.250000, 100 }
102. { SELL, 101.750000, 25 }
103. { BUY, 100.500000, 75 }
104. { SELL, 100.750000, 75 }
105. { SELL, 100.250000, 100 }
106. { BUY, 101.500000, 100 }
107. { SELL, 100.000000, 75 }
108. { BUY, 101.000000, 50 }
109. { SELL, 100.750000, 75 }
110. { SELL, 100.000000, 50 }
111. { BUY, 102.000000, 50 }
112. { BUY, 101.000000, 50 }
113. { SELL, 100.500000, 25 }
114. { SELL, 100.500000, 50 }
115. { SELL, 100.000000, 50 }
116. { SELL, 101.500000, 75 }
117. { SELL, 101.750000, 25 }
118. { SELL, 101.250000, 75 }
119. { BUY, 101.000000, 75 }
120. { BUY, 100.500000, 75 }
121. { SELL, 100.500000, 25 }
122. { SELL, 101.750000, 25 }
123. { BUY, 100.250000, 50 }
124. { SELL, 100.000000, 100 }
125. { BUY, 101.750000, 50 }
126. { BUY, 100.250000, 100 }
127. { SELL, 101.000000, 100 }
128. { SELL, 101.750000, 75 }
129. { BUY, 101.500000, 75 }
130. { SELL, 102.000000, 100 }
131. { BUY, 100.750000, 50 }
132. { BUY, 102.000000, 75 }
133. { BUY, 100.500000, 25 }
134. { BUY, 101.250000, 25 }
135. { BUY, 101.000000, 25 }
136. { BUY, 101.000000, 75 }
137. { SELL, 101.750000, 25 }
138. { SELL, 100.500000, 100 }
139. { SELL, 102.000000, 100 }
140. { BUY, 101.750000, 50 }
141. { BUY, 101.500000, 75 }
142. { BUY, 100.750000, 50 }
143. { SELL, 101.500000, 100 }
144. { SELL, 102.000000, 75 }
145. { BUY, 101.250000, 50 }
146. { BUY, 100.500000, 25 }
147. { BUY, 100.000000, 25 }
148. { SELL, 101.500000, 50 }
149. { SELL, 100.500000, 25 }
150. { SELL, 100.500000, 100 }
151. { SELL, 101.750000, 100 }
152. { SELL, 101.250000, 75 }
153. { SELL, 100.000000, 100 }
154. { SELL, 101.750000, 25 }
155. { BUY, 100.000000, 50 }
156. { SELL, 101.000000, 50 }
157. { SELL, 100.500000, 50 }
158. { BUY, 101.000000, 100 }
159. { BUY, 101.500000, 25 }
160. { SELL, 101.000000, 100 }
161. { SELL, 100.750000, 50 }
162. { BUY, 101.500000, 75 }
163. { SELL, 102.000000, 25 }
164. { SELL, 101.000000, 75 }
165. { SELL, 100.750000, 50 }
166. { BUY, 100.250000, 50 }
167. { BUY, 100.500000, 75 }
168. { BUY, 101.250000, 75 }
169. { SELL, 102.000000, 50 }
170. { BUY, 100.250000, 50 }
171. { BUY, 101.250000, 75 }
172. { SELL, 100.500000, 25 }
173. { SELL, 101.000000, 75 }
174. { SELL, 101.500000, 100 }
175. { BUY, 102.000000, 75 }
176. { BUY, 101.250000, 75 }
177. { SELL, 101.000000, 75 }
178. { SELL, 101.250000, 75 }
179. { BUY, 101.750000, 75 }
180. { SELL, 101.750000, 100 }
181. { BUY, 101.000000, 75 }
182. { SELL, 100.750000, 100 }
183. { SELL, 101.750000, 75 }
184. { BUY, 102.000000, 50 }
185. { SELL, 100.000000, 100 }
186. { SELL, 101.250000, 50 }
187. { BUY, 101.750000, 25 }
188. { SELL, 100.250000, 75 }
189. { BUY, 100.000000, 25 }
190. { SELL, 101.000000, 25 }
191. { BUY, 101.750000, 100 }
192. { BUY, 101.250000, 50 }
193. { BUY, 101.750000, 50 }
194. { SELL, 100.000000, 75 }
195. { BUY, 100.500000, 100 }
196. { SELL, 100.250000, 75 }
197. { BUY, 100.750000, 100 }
198. { BUY, 101.500000, 50 }
199. { SELL, 101.500000, 75 }
200. { SELL, 100.750000, 100 }
201. { SELL, 100.750000, 100 }
202. { BUY, 100.250000, 75 }
203. { BUY, 101.500000, 50 }
204. { SELL, 101.750000, 50 }
205. { BUY, 100.000000, 75 }
206. { BUY, 101.500000, 25 }
207. { BUY, 100.250000, 25 }
208. { SELL, 100.000000, 100 }
209. { SELL, 102.000000, 75 }
210. { BUY, 100.500000, 75 }
211. { BUY, 100.000000, 75 }
212. { BUY, 101.750000, 75 }
213. { BUY, 101.000000, 75 }
214. { SELL, 100.000000, 25 }
215. { BUY, 100.750000, 25 }
216. { BUY, 101.750000, 75 }
217. { SELL, 101.000000, 50 }
218. { BUY, 101.750000, 25 }
219. { BUY, 100.500000, 100 }
220. { SELL, 101.500000, 50 }
221. { SELL, 101.000000, 50 }
222. { SELL, 101.500000, 75 }
223. { SELL, 101.750000, 25 }
224. { SELL, 101.750000, 100 }
225. { BUY, 100.500000, 25 }
226. { BUY, 101.000000, 75 }
227. { SELL, 101.500000, 25 }
228. { SELL, 101.750000, 100 }
229. { SELL, 102.000000, 75 }
230. { SELL, 101.250000, 100 }
231. { BUY, 101.500000, 100 }
232. { SELL, 101.750000, 25 }
233. { SELL, 100.000000, 25 }
234. { BUY, 100.750000, 75 }
235. { BUY, 101.000000, 75 }
236. { BUY, 101.500000, 50 }
237. { BUY, 100.750000, 100 }
238. { BUY, 101.000000, 100 }
239. { SELL, 101.750000, 25 }
240. { BUY, 100.000000, 50 }
241. { BUY, 100.000000, 50 }
242. { BUY, 101.500000, 100 }
243. { BUY, 101.000000, 25 }
244. { SELL, 102.000000, 50 }
245. { BUY, 101.500000, 25 }
246. { BUY, 100.500000, 75 }
247. { SELL, 100.000000, 75 }
248. { SELL, 101.500000, 50 }
249. { SELL, 102.000000, 50 }
250. { SELL, 100.000000, 25 }
251. { BUY, 100.250000, 75 }
252. { BUY, 100.000000, 75 }
253. { SELL, 101.250000, 25 }
254. { SELL, 101.750000, 50 }
255. { BUY, 101.500000, 100 }
256. { SELL, 101.750000, 75 }
257. { BUY, 101.500000, 100 }
258. { BUY, 100.000000, 75 }
259. { BUY, 100.250000, 100 }
260. { SELL, 100.500000, 25 }
261. { SELL, 101.000000, 100 }
